ERROR 2025-05-12 16:07:10,437 basehttp You're accessing the development server over HTTPS, but it only supports HTTP.
ERROR 2025-05-12 16:07:10,452 basehttp You're accessing the development server over HTTPS, but it only supports HTTP.
ERROR 2025-05-12 16:07:15,286 basehttp You're accessing the development server over HTTPS, but it only supports HTTP.
ERROR 2025-05-12 16:07:15,294 basehttp You're accessing the development server over HTTPS, but it only supports HTTP.
ERROR 2025-05-12 16:11:43,759 basehttp You're accessing the development server over HTTPS, but it only supports HTTP.
ERROR 2025-05-12 16:11:43,783 basehttp You're accessing the development server over HTTPS, but it only supports HTTP.
ERROR 2025-05-12 16:47:49,964 basehttp You're accessing the development server over HTTPS, but it only supports HTTP.
ERROR 2025-05-12 16:47:50,005 basehttp You're accessing the development server over HTTPS, but it only supports HTTP.
ERROR 2025-05-12 16:48:03,659 basehttp You're accessing the development server over HTTPS, but it only supports HTTP.
ERROR 2025-05-12 16:48:03,671 basehttp You're accessing the development server over HTTPS, but it only supports HTTP.
ERROR 2025-05-12 16:57:24,651 basehttp You're accessing the development server over HTTPS, but it only supports HTTP.
ERROR 2025-05-12 16:57:24,665 basehttp You're accessing the development server over HTTPS, but it only supports HTTP.
ERROR 2025-05-12 16:57:24,674 basehttp You're accessing the development server over HTTPS, but it only supports HTTP.
ERROR 2025-05-12 16:57:27,048 basehttp You're accessing the development server over HTTPS, but it only supports HTTP.
ERROR 2025-05-12 16:57:27,057 basehttp You're accessing the development server over HTTPS, but it only supports HTTP.
ERROR 2025-05-12 16:57:27,065 basehttp You're accessing the development server over HTTPS, but it only supports HTTP.
ERROR 2025-05-12 16:57:30,048 basehttp You're accessing the development server over HTTPS, but it only supports HTTP.
ERROR 2025-05-12 16:57:30,056 basehttp You're accessing the development server over HTTPS, but it only supports HTTP.
ERROR 2025-05-12 16:57:30,070 basehttp You're accessing the development server over HTTPS, but it only supports HTTP.
ERROR 2025-05-12 16:57:41,550 basehttp You're accessing the development server over HTTPS, but it only supports HTTP.
ERROR 2025-05-12 16:57:41,558 basehttp You're accessing the development server over HTTPS, but it only supports HTTP.
ERROR 2025-05-12 17:01:27,947 basehttp You're accessing the development server over HTTPS, but it only supports HTTP.
ERROR 2025-05-12 17:01:27,958 basehttp You're accessing the development server over HTTPS, but it only supports HTTP.
ERROR 2025-05-12 17:01:27,967 basehttp You're accessing the development server over HTTPS, but it only supports HTTP.
ERROR 2025-05-14 07:50:07,650 basehttp You're accessing the development server over HTTPS, but it only supports HTTP.
ERROR 2025-05-14 07:50:07,657 basehttp You're accessing the development server over HTTPS, but it only supports HTTP.
ERROR 2025-05-14 07:50:39,619 basehttp You're accessing the development server over HTTPS, but it only supports HTTP.
ERROR 2025-05-14 07:50:39,646 basehttp You're accessing the development server over HTTPS, but it only supports HTTP.
ERROR 2025-05-14 07:50:39,665 basehttp You're accessing the development server over HTTPS, but it only supports HTTP.
ERROR 2025-05-14 07:51:52,861 basehttp You're accessing the development server over HTTPS, but it only supports HTTP.
ERROR 2025-05-14 07:51:52,873 basehttp You're accessing the development server over HTTPS, but it only supports HTTP.
ERROR 2025-05-14 08:12:48,534 basehttp You're accessing the development server over HTTPS, but it only supports HTTP.
ERROR 2025-05-14 08:28:55,898 basehttp You're accessing the development server over HTTPS, but it only supports HTTP.
ERROR 2025-05-14 08:28:55,908 basehttp You're accessing the development server over HTTPS, but it only supports HTTP.
ERROR 2025-05-14 08:29:00,783 basehttp You're accessing the development server over HTTPS, but it only supports HTTP.
ERROR 2025-05-14 08:29:00,803 basehttp You're accessing the development server over HTTPS, but it only supports HTTP.
ERROR 2025-05-14 08:29:00,819 basehttp You're accessing the development server over HTTPS, but it only supports HTTP.
ERROR 2025-05-14 08:46:02,918 log Internal Server Error: /interacciones/registrar/
Traceback (most recent call last):
  File "/home/kaleyvo/Escritorio/dc/venv/lib/python3.12/site-packages/django/core/handlers/exception.py", line 55, in inner
    response = get_response(request)
               ^^^^^^^^^^^^^^^^^^^^^
  File "/home/kaleyvo/Escritorio/dc/venv/lib/python3.12/site-packages/django/core/handlers/base.py", line 197, in _get_response
    response = wrapped_callback(request, *callback_args, **callback_kwargs)
               ^^^^^^^^^^^^^^^^^^^^^^^^^^^^^^^^^^^^^^^^^^^^^^^^^^^^^^^^^^^^
  File "/home/kaleyvo/Escritorio/dc/venv/lib/python3.12/site-packages/django/views/decorators/csrf.py", line 56, in wrapper_view
    return view_func(*args, **kwargs)
           ^^^^^^^^^^^^^^^^^^^^^^^^^^
  File "/home/kaleyvo/Escritorio/dc/venv/lib/python3.12/site-packages/django/views/generic/base.py", line 104, in view
    return self.dispatch(request, *args, **kwargs)
           ^^^^^^^^^^^^^^^^^^^^^^^^^^^^^^^^^^^^^^^
  File "/home/kaleyvo/Escritorio/dc/venv/lib/python3.12/site-packages/rest_framework/views.py", line 515, in dispatch
    response = self.handle_exception(exc)
               ^^^^^^^^^^^^^^^^^^^^^^^^^^
  File "/home/kaleyvo/Escritorio/dc/venv/lib/python3.12/site-packages/rest_framework/views.py", line 475, in handle_exception
    self.raise_uncaught_exception(exc)
  File "/home/kaleyvo/Escritorio/dc/venv/lib/python3.12/site-packages/rest_framework/views.py", line 486, in raise_uncaught_exception
    raise exc
  File "/home/kaleyvo/Escritorio/dc/venv/lib/python3.12/site-packages/rest_framework/views.py", line 512, in dispatch
    response = handler(request, *args, **kwargs)
               ^^^^^^^^^^^^^^^^^^^^^^^^^^^^^^^^^
  File "/home/kaleyvo/Escritorio/dc/interacciones/views.py", line 20, in post
    if serializer.is_valid():
       ^^^^^^^^^^^^^^^^^^^^^
  File "/home/kaleyvo/Escritorio/dc/venv/lib/python3.12/site-packages/rest_framework/serializers.py", line 225, in is_valid
    self._validated_data = self.run_validation(self.initial_data)
                           ^^^^^^^^^^^^^^^^^^^^^^^^^^^^^^^^^^^^^^
  File "/home/kaleyvo/Escritorio/dc/venv/lib/python3.12/site-packages/rest_framework/serializers.py", line 444, in run_validation
    value = self.to_internal_value(data)
            ^^^^^^^^^^^^^^^^^^^^^^^^^^^^
  File "/home/kaleyvo/Escritorio/dc/venv/lib/python3.12/site-packages/rest_framework/serializers.py", line 497, in to_internal_value
    for field in fields:
  File "/home/kaleyvo/Escritorio/dc/venv/lib/python3.12/site-packages/rest_framework/serializers.py", line 380, in _writable_fields
    for field in self.fields.values():
                 ^^^^^^^^^^^
  File "/home/kaleyvo/Escritorio/dc/venv/lib/python3.12/site-packages/django/utils/functional.py", line 57, in __get__
    res = instance.__dict__[self.name] = self.func(instance)
                                         ^^^^^^^^^^^^^^^^^^^
  File "/home/kaleyvo/Escritorio/dc/venv/lib/python3.12/site-packages/rest_framework/serializers.py", line 374, in fields
    for key, value in self.get_fields().items():
                      ^^^^^^^^^^^^^^^^^
  File "/home/kaleyvo/Escritorio/dc/venv/lib/python3.12/site-packages/rest_framework/serializers.py", line 1081, in get_fields
    field_names = self.get_field_names(declared_fields, info)
                  ^^^^^^^^^^^^^^^^^^^^^^^^^^^^^^^^^^^^^^^^^^^
  File "/home/kaleyvo/Escritorio/dc/venv/lib/python3.12/site-packages/rest_framework/serializers.py", line 1135, in get_field_names
    raise TypeError(
TypeError: The `fields` option must be a list or tuple or "__all__". Got str.
ERROR 2025-05-14 08:46:02,986 basehttp "POST /interacciones/registrar/ HTTP/1.1" 500 145
ERROR 2025-05-14 08:58:52,736 log Internal Server Error: /interacciones/registrar/
Traceback (most recent call last):
  File "/home/kaleyvo/Escritorio/dc/venv/lib/python3.12/site-packages/django/core/handlers/exception.py", line 55, in inner
    response = get_response(request)
               ^^^^^^^^^^^^^^^^^^^^^
  File "/home/kaleyvo/Escritorio/dc/venv/lib/python3.12/site-packages/django/core/handlers/base.py", line 197, in _get_response
    response = wrapped_callback(request, *callback_args, **callback_kwargs)
               ^^^^^^^^^^^^^^^^^^^^^^^^^^^^^^^^^^^^^^^^^^^^^^^^^^^^^^^^^^^^
  File "/home/kaleyvo/Escritorio/dc/venv/lib/python3.12/site-packages/django/views/decorators/csrf.py", line 56, in wrapper_view
    return view_func(*args, **kwargs)
           ^^^^^^^^^^^^^^^^^^^^^^^^^^
  File "/home/kaleyvo/Escritorio/dc/venv/lib/python3.12/site-packages/django/views/generic/base.py", line 104, in view
    return self.dispatch(request, *args, **kwargs)
           ^^^^^^^^^^^^^^^^^^^^^^^^^^^^^^^^^^^^^^^
  File "/home/kaleyvo/Escritorio/dc/venv/lib/python3.12/site-packages/rest_framework/views.py", line 515, in dispatch
    response = self.handle_exception(exc)
               ^^^^^^^^^^^^^^^^^^^^^^^^^^
  File "/home/kaleyvo/Escritorio/dc/venv/lib/python3.12/site-packages/rest_framework/views.py", line 475, in handle_exception
    self.raise_uncaught_exception(exc)
  File "/home/kaleyvo/Escritorio/dc/venv/lib/python3.12/site-packages/rest_framework/views.py", line 486, in raise_uncaught_exception
    raise exc
  File "/home/kaleyvo/Escritorio/dc/venv/lib/python3.12/site-packages/rest_framework/views.py", line 512, in dispatch
    response = handler(request, *args, **kwargs)
               ^^^^^^^^^^^^^^^^^^^^^^^^^^^^^^^^^
  File "/home/kaleyvo/Escritorio/dc/interacciones/views.py", line 20, in post
    if serializer.is_valid():
       ^^^^^^^^^^^^^^^^^^^^^
  File "/home/kaleyvo/Escritorio/dc/venv/lib/python3.12/site-packages/rest_framework/serializers.py", line 225, in is_valid
    self._validated_data = self.run_validation(self.initial_data)
                           ^^^^^^^^^^^^^^^^^^^^^^^^^^^^^^^^^^^^^^
  File "/home/kaleyvo/Escritorio/dc/venv/lib/python3.12/site-packages/rest_framework/serializers.py", line 444, in run_validation
    value = self.to_internal_value(data)
            ^^^^^^^^^^^^^^^^^^^^^^^^^^^^
  File "/home/kaleyvo/Escritorio/dc/venv/lib/python3.12/site-packages/rest_framework/serializers.py", line 497, in to_internal_value
    for field in fields:
  File "/home/kaleyvo/Escritorio/dc/venv/lib/python3.12/site-packages/rest_framework/serializers.py", line 380, in _writable_fields
    for field in self.fields.values():
                 ^^^^^^^^^^^
  File "/home/kaleyvo/Escritorio/dc/venv/lib/python3.12/site-packages/django/utils/functional.py", line 57, in __get__
    res = instance.__dict__[self.name] = self.func(instance)
                                         ^^^^^^^^^^^^^^^^^^^
  File "/home/kaleyvo/Escritorio/dc/venv/lib/python3.12/site-packages/rest_framework/serializers.py", line 374, in fields
    for key, value in self.get_fields().items():
                      ^^^^^^^^^^^^^^^^^
  File "/home/kaleyvo/Escritorio/dc/venv/lib/python3.12/site-packages/rest_framework/serializers.py", line 1081, in get_fields
    field_names = self.get_field_names(declared_fields, info)
                  ^^^^^^^^^^^^^^^^^^^^^^^^^^^^^^^^^^^^^^^^^^^
  File "/home/kaleyvo/Escritorio/dc/venv/lib/python3.12/site-packages/rest_framework/serializers.py", line 1135, in get_field_names
    raise TypeError(
TypeError: The `fields` option must be a list or tuple or "__all__". Got str.
ERROR 2025-05-14 08:58:52,747 basehttp "POST /interacciones/registrar/ HTTP/1.1" 500 145
ERROR 2025-05-14 09:18:01,065 basehttp You're accessing the development server over HTTPS, but it only supports HTTP.
ERROR 2025-05-14 09:18:01,076 basehttp You're accessing the development server over HTTPS, but it only supports HTTP.
ERROR 2025-05-14 09:20:09,256 log Internal Server Error: /interacciones/registrar/
Traceback (most recent call last):
  File "/home/kaleyvo/Escritorio/dc/venv/lib/python3.12/site-packages/django/core/handlers/exception.py", line 55, in inner
    response = get_response(request)
               ^^^^^^^^^^^^^^^^^^^^^
  File "/home/kaleyvo/Escritorio/dc/venv/lib/python3.12/site-packages/django/core/handlers/base.py", line 197, in _get_response
    response = wrapped_callback(request, *callback_args, **callback_kwargs)
               ^^^^^^^^^^^^^^^^^^^^^^^^^^^^^^^^^^^^^^^^^^^^^^^^^^^^^^^^^^^^
  File "/home/kaleyvo/Escritorio/dc/venv/lib/python3.12/site-packages/django/views/decorators/csrf.py", line 56, in wrapper_view
    return view_func(*args, **kwargs)
           ^^^^^^^^^^^^^^^^^^^^^^^^^^
  File "/home/kaleyvo/Escritorio/dc/venv/lib/python3.12/site-packages/django/views/generic/base.py", line 104, in view
    return self.dispatch(request, *args, **kwargs)
           ^^^^^^^^^^^^^^^^^^^^^^^^^^^^^^^^^^^^^^^
  File "/home/kaleyvo/Escritorio/dc/venv/lib/python3.12/site-packages/rest_framework/views.py", line 515, in dispatch
    response = self.handle_exception(exc)
               ^^^^^^^^^^^^^^^^^^^^^^^^^^
  File "/home/kaleyvo/Escritorio/dc/venv/lib/python3.12/site-packages/rest_framework/views.py", line 475, in handle_exception
    self.raise_uncaught_exception(exc)
  File "/home/kaleyvo/Escritorio/dc/venv/lib/python3.12/site-packages/rest_framework/views.py", line 486, in raise_uncaught_exception
    raise exc
  File "/home/kaleyvo/Escritorio/dc/venv/lib/python3.12/site-packages/rest_framework/views.py", line 512, in dispatch
    response = handler(request, *args, **kwargs)
               ^^^^^^^^^^^^^^^^^^^^^^^^^^^^^^^^^
  File "/home/kaleyvo/Escritorio/dc/interacciones/views.py", line 21, in post
    if serializer.is_valid():
       ^^^^^^^^^^^^^^^^^^^^^
  File "/home/kaleyvo/Escritorio/dc/venv/lib/python3.12/site-packages/rest_framework/serializers.py", line 225, in is_valid
    self._validated_data = self.run_validation(self.initial_data)
                           ^^^^^^^^^^^^^^^^^^^^^^^^^^^^^^^^^^^^^^
  File "/home/kaleyvo/Escritorio/dc/venv/lib/python3.12/site-packages/rest_framework/serializers.py", line 444, in run_validation
    value = self.to_internal_value(data)
            ^^^^^^^^^^^^^^^^^^^^^^^^^^^^
  File "/home/kaleyvo/Escritorio/dc/venv/lib/python3.12/site-packages/rest_framework/serializers.py", line 497, in to_internal_value
    for field in fields:
  File "/home/kaleyvo/Escritorio/dc/venv/lib/python3.12/site-packages/rest_framework/serializers.py", line 380, in _writable_fields
    for field in self.fields.values():
                 ^^^^^^^^^^^
  File "/home/kaleyvo/Escritorio/dc/venv/lib/python3.12/site-packages/django/utils/functional.py", line 57, in __get__
    res = instance.__dict__[self.name] = self.func(instance)
                                         ^^^^^^^^^^^^^^^^^^^
  File "/home/kaleyvo/Escritorio/dc/venv/lib/python3.12/site-packages/rest_framework/serializers.py", line 374, in fields
    for key, value in self.get_fields().items():
                      ^^^^^^^^^^^^^^^^^
  File "/home/kaleyvo/Escritorio/dc/venv/lib/python3.12/site-packages/rest_framework/serializers.py", line 1081, in get_fields
    field_names = self.get_field_names(declared_fields, info)
                  ^^^^^^^^^^^^^^^^^^^^^^^^^^^^^^^^^^^^^^^^^^^
  File "/home/kaleyvo/Escritorio/dc/venv/lib/python3.12/site-packages/rest_framework/serializers.py", line 1135, in get_field_names
    raise TypeError(
TypeError: The `fields` option must be a list or tuple or "__all__". Got str.
ERROR 2025-05-14 09:20:09,269 basehttp "POST /interacciones/registrar/ HTTP/1.1" 500 145
ERROR 2025-05-14 11:28:37,066 basehttp You're accessing the development server over HTTPS, but it only supports HTTP.
ERROR 2025-05-14 11:28:37,080 basehttp You're accessing the development server over HTTPS, but it only supports HTTP.
ERROR 2025-05-14 11:28:37,089 basehttp You're accessing the development server over HTTPS, but it only supports HTTP.
ERROR 2025-05-14 11:55:27,326 log Internal Server Error: /api/users/
Traceback (most recent call last):
  File "/home/kaleyvo/Escritorio/dc/venv/lib/python3.12/site-packages/django/core/handlers/exception.py", line 55, in inner
    response = get_response(request)
               ^^^^^^^^^^^^^^^^^^^^^
  File "/home/kaleyvo/Escritorio/dc/venv/lib/python3.12/site-packages/django/core/handlers/base.py", line 197, in _get_response
    response = wrapped_callback(request, *callback_args, **callback_kwargs)
               ^^^^^^^^^^^^^^^^^^^^^^^^^^^^^^^^^^^^^^^^^^^^^^^^^^^^^^^^^^^^
  File "/home/kaleyvo/Escritorio/dc/venv/lib/python3.12/site-packages/django/views/decorators/csrf.py", line 56, in wrapper_view
    return view_func(*args, **kwargs)
           ^^^^^^^^^^^^^^^^^^^^^^^^^^
  File "/home/kaleyvo/Escritorio/dc/venv/lib/python3.12/site-packages/django/views/generic/base.py", line 104, in view
    return self.dispatch(request, *args, **kwargs)
           ^^^^^^^^^^^^^^^^^^^^^^^^^^^^^^^^^^^^^^^
  File "/home/kaleyvo/Escritorio/dc/venv/lib/python3.12/site-packages/rest_framework/views.py", line 515, in dispatch
    response = self.handle_exception(exc)
               ^^^^^^^^^^^^^^^^^^^^^^^^^^
  File "/home/kaleyvo/Escritorio/dc/venv/lib/python3.12/site-packages/rest_framework/views.py", line 475, in handle_exception
    self.raise_uncaught_exception(exc)
  File "/home/kaleyvo/Escritorio/dc/venv/lib/python3.12/site-packages/rest_framework/views.py", line 486, in raise_uncaught_exception
    raise exc
  File "/home/kaleyvo/Escritorio/dc/venv/lib/python3.12/site-packages/rest_framework/views.py", line 503, in dispatch
    self.initial(request, *args, **kwargs)
  File "/home/kaleyvo/Escritorio/dc/venv/lib/python3.12/site-packages/rest_framework/views.py", line 421, in initial
    self.check_permissions(request)
  File "/home/kaleyvo/Escritorio/dc/venv/lib/python3.12/site-packages/rest_framework/views.py", line 338, in check_permissions
    if not permission.has_permission(request, self):
           ^^^^^^^^^^^^^^^^^^^^^^^^^^^^^^^^^^^^^^^^
  File "/home/kaleyvo/Escritorio/dc/venv/lib/python3.12/site-packages/rest_framework/permissions.py", line 243, in has_permission
    queryset = self._queryset(view)
               ^^^^^^^^^^^^^^^^^^^^
  File "/home/kaleyvo/Escritorio/dc/venv/lib/python3.12/site-packages/rest_framework/permissions.py", line 219, in _queryset
    assert hasattr(view, 'get_queryset') \
           ^^^^^^^^^^^^^^^^^^^^^^^^^^^^^^^
AssertionError: Cannot apply DjangoModelPermissions on a view that does not set `.queryset` or have a `.get_queryset()` method.
ERROR 2025-05-14 11:55:27,371 basehttp "GET /api/users/ HTTP/1.1" 500 145
ERROR 2025-05-14 12:02:48,903 log Internal Server Error: /api/users/
Traceback (most recent call last):
  File "/home/kaleyvo/Escritorio/dc/venv/lib/python3.12/site-packages/django/core/handlers/exception.py", line 55, in inner
    response = get_response(request)
               ^^^^^^^^^^^^^^^^^^^^^
  File "/home/kaleyvo/Escritorio/dc/venv/lib/python3.12/site-packages/django/core/handlers/base.py", line 197, in _get_response
    response = wrapped_callback(request, *callback_args, **callback_kwargs)
               ^^^^^^^^^^^^^^^^^^^^^^^^^^^^^^^^^^^^^^^^^^^^^^^^^^^^^^^^^^^^
  File "/home/kaleyvo/Escritorio/dc/venv/lib/python3.12/site-packages/django/views/decorators/csrf.py", line 56, in wrapper_view
    return view_func(*args, **kwargs)
           ^^^^^^^^^^^^^^^^^^^^^^^^^^
  File "/home/kaleyvo/Escritorio/dc/venv/lib/python3.12/site-packages/django/views/generic/base.py", line 104, in view
    return self.dispatch(request, *args, **kwargs)
           ^^^^^^^^^^^^^^^^^^^^^^^^^^^^^^^^^^^^^^^
  File "/home/kaleyvo/Escritorio/dc/venv/lib/python3.12/site-packages/rest_framework/views.py", line 515, in dispatch
    response = self.handle_exception(exc)
               ^^^^^^^^^^^^^^^^^^^^^^^^^^
  File "/home/kaleyvo/Escritorio/dc/venv/lib/python3.12/site-packages/rest_framework/views.py", line 475, in handle_exception
    self.raise_uncaught_exception(exc)
  File "/home/kaleyvo/Escritorio/dc/venv/lib/python3.12/site-packages/rest_framework/views.py", line 486, in raise_uncaught_exception
    raise exc
  File "/home/kaleyvo/Escritorio/dc/venv/lib/python3.12/site-packages/rest_framework/views.py", line 503, in dispatch
    self.initial(request, *args, **kwargs)
  File "/home/kaleyvo/Escritorio/dc/venv/lib/python3.12/site-packages/rest_framework/views.py", line 421, in initial
    self.check_permissions(request)
  File "/home/kaleyvo/Escritorio/dc/venv/lib/python3.12/site-packages/rest_framework/views.py", line 338, in check_permissions
    if not permission.has_permission(request, self):
           ^^^^^^^^^^^^^^^^^^^^^^^^^^^^^^^^^^^^^^^^
  File "/home/kaleyvo/Escritorio/dc/venv/lib/python3.12/site-packages/rest_framework/permissions.py", line 243, in has_permission
    queryset = self._queryset(view)
               ^^^^^^^^^^^^^^^^^^^^
  File "/home/kaleyvo/Escritorio/dc/venv/lib/python3.12/site-packages/rest_framework/permissions.py", line 219, in _queryset
    assert hasattr(view, 'get_queryset') \
           ^^^^^^^^^^^^^^^^^^^^^^^^^^^^^^^
AssertionError: Cannot apply DjangoModelPermissions on a view that does not set `.queryset` or have a `.get_queryset()` method.
ERROR 2025-05-14 12:02:48,909 basehttp "GET /api/users/ HTTP/1.1" 500 145
ERROR 2025-05-14 12:03:24,715 basehttp You're accessing the development server over HTTPS, but it only supports HTTP.
ERROR 2025-05-14 12:03:24,736 basehttp You're accessing the development server over HTTPS, but it only supports HTTP.
ERROR 2025-05-14 14:09:03,682 log Internal Server Error: /admin/login/
Traceback (most recent call last):
  File "/home/kaleyvo/Escritorio/dc/venv/lib/python3.12/site-packages/django/core/handlers/exception.py", line 55, in inner
    response = get_response(request)
               ^^^^^^^^^^^^^^^^^^^^^
  File "/home/kaleyvo/Escritorio/dc/venv/lib/python3.12/site-packages/django/core/handlers/base.py", line 197, in _get_response
    response = wrapped_callback(request, *callback_args, **callback_kwargs)
               ^^^^^^^^^^^^^^^^^^^^^^^^^^^^^^^^^^^^^^^^^^^^^^^^^^^^^^^^^^^^
  File "/home/kaleyvo/Escritorio/dc/venv/lib/python3.12/site-packages/django/utils/decorators.py", line 48, in _wrapper
    return bound_method(*args, **kwargs)
           ^^^^^^^^^^^^^^^^^^^^^^^^^^^^^
  File "/home/kaleyvo/Escritorio/dc/venv/lib/python3.12/site-packages/django/views/decorators/cache.py", line 80, in _view_wrapper
    response = view_func(request, *args, **kwargs)
               ^^^^^^^^^^^^^^^^^^^^^^^^^^^^^^^^^^^
  File "/home/kaleyvo/Escritorio/dc/venv/lib/python3.12/site-packages/django/contrib/admin/sites.py", line 449, in login
    return LoginView.as_view(**defaults)(request)
           ^^^^^^^^^^^^^^^^^^^^^^^^^^^^^^^^^^^^^^
  File "/home/kaleyvo/Escritorio/dc/venv/lib/python3.12/site-packages/django/views/generic/base.py", line 104, in view
    return self.dispatch(request, *args, **kwargs)
           ^^^^^^^^^^^^^^^^^^^^^^^^^^^^^^^^^^^^^^^
  File "/home/kaleyvo/Escritorio/dc/venv/lib/python3.12/site-packages/django/utils/decorators.py", line 48, in _wrapper
    return bound_method(*args, **kwargs)
           ^^^^^^^^^^^^^^^^^^^^^^^^^^^^^
  File "/home/kaleyvo/Escritorio/dc/venv/lib/python3.12/site-packages/django/utils/decorators.py", line 48, in _wrapper
    return bound_method(*args, **kwargs)
           ^^^^^^^^^^^^^^^^^^^^^^^^^^^^^
  File "/home/kaleyvo/Escritorio/dc/venv/lib/python3.12/site-packages/django/views/decorators/debug.py", line 143, in sensitive_post_parameters_wrapper
    return view(request, *args, **kwargs)
           ^^^^^^^^^^^^^^^^^^^^^^^^^^^^^^
  File "/home/kaleyvo/Escritorio/dc/venv/lib/python3.12/site-packages/django/utils/decorators.py", line 48, in _wrapper
    return bound_method(*args, **kwargs)
           ^^^^^^^^^^^^^^^^^^^^^^^^^^^^^
  File "/home/kaleyvo/Escritorio/dc/venv/lib/python3.12/site-packages/django/utils/decorators.py", line 192, in _view_wrapper
    result = _process_exception(request, e)
             ^^^^^^^^^^^^^^^^^^^^^^^^^^^^^^
  File "/home/kaleyvo/Escritorio/dc/venv/lib/python3.12/site-packages/django/utils/decorators.py", line 190, in _view_wrapper
    response = view_func(request, *args, **kwargs)
               ^^^^^^^^^^^^^^^^^^^^^^^^^^^^^^^^^^^
  File "/home/kaleyvo/Escritorio/dc/venv/lib/python3.12/site-packages/django/utils/decorators.py", line 48, in _wrapper
    return bound_method(*args, **kwargs)
           ^^^^^^^^^^^^^^^^^^^^^^^^^^^^^
  File "/home/kaleyvo/Escritorio/dc/venv/lib/python3.12/site-packages/django/views/decorators/cache.py", line 80, in _view_wrapper
    response = view_func(request, *args, **kwargs)
               ^^^^^^^^^^^^^^^^^^^^^^^^^^^^^^^^^^^
  File "/home/kaleyvo/Escritorio/dc/venv/lib/python3.12/site-packages/django/contrib/auth/views.py", line 89, in dispatch
    return super().dispatch(request, *args, **kwargs)
           ^^^^^^^^^^^^^^^^^^^^^^^^^^^^^^^^^^^^^^^^^^
  File "/home/kaleyvo/Escritorio/dc/venv/lib/python3.12/site-packages/django/views/generic/base.py", line 143, in dispatch
    return handler(request, *args, **kwargs)
           ^^^^^^^^^^^^^^^^^^^^^^^^^^^^^^^^^
  File "/home/kaleyvo/Escritorio/dc/venv/lib/python3.12/site-packages/django/views/generic/edit.py", line 151, in post
    return self.form_valid(form)
           ^^^^^^^^^^^^^^^^^^^^^
  File "/home/kaleyvo/Escritorio/dc/venv/lib/python3.12/site-packages/django/contrib/auth/views.py", line 108, in form_valid
    auth_login(self.request, form.get_user())
  File "/home/kaleyvo/Escritorio/dc/venv/lib/python3.12/site-packages/django/contrib/auth/__init__.py", line 197, in login
    user_logged_in.send(sender=user.__class__, request=request, user=user)
  File "/home/kaleyvo/Escritorio/dc/venv/lib/python3.12/site-packages/django/dispatch/dispatcher.py", line 189, in send
    response = receiver(signal=self, sender=sender, **named)
               ^^^^^^^^^^^^^^^^^^^^^^^^^^^^^^^^^^^^^^^^^^^^^
  File "/home/kaleyvo/Escritorio/dc/venv/lib/python3.12/site-packages/django/contrib/auth/models.py", line 24, in update_last_login
    user.save(update_fields=["last_login"])
  File "/home/kaleyvo/Escritorio/dc/venv/lib/python3.12/site-packages/django/contrib/auth/base_user.py", line 65, in save
    super().save(*args, **kwargs)
  File "/home/kaleyvo/Escritorio/dc/venv/lib/python3.12/site-packages/django/db/models/base.py", line 902, in save
    self.save_base(
  File "/home/kaleyvo/Escritorio/dc/venv/lib/python3.12/site-packages/django/db/models/base.py", line 1023, in save_base
    post_save.send(
  File "/home/kaleyvo/Escritorio/dc/venv/lib/python3.12/site-packages/django/dispatch/dispatcher.py", line 189, in send
    response = receiver(signal=self, sender=sender, **named)
               ^^^^^^^^^^^^^^^^^^^^^^^^^^^^^^^^^^^^^^^^^^^^^
  File "/home/kaleyvo/Escritorio/dc/users/signals.py", line 12, in save_profile
    instance.profile.save()
    ^^^^^^^^^^^^^^^^
  File "/home/kaleyvo/Escritorio/dc/venv/lib/python3.12/site-packages/django/db/models/fields/related_descriptors.py", line 531, in __get__
    raise self.RelatedObjectDoesNotExist(
users.models.user.CustomUser.profile.RelatedObjectDoesNotExist: CustomUser has no profile.
ERROR 2025-05-14 14:09:03,814 basehttp "POST /admin/login/?next=/admin/ HTTP/1.1" 500 145
ERROR 2025-05-14 14:09:43,833 log Internal Server Error: /admin/login/
Traceback (most recent call last):
  File "/home/kaleyvo/Escritorio/dc/venv/lib/python3.12/site-packages/django/core/handlers/exception.py", line 55, in inner
    response = get_response(request)
               ^^^^^^^^^^^^^^^^^^^^^
  File "/home/kaleyvo/Escritorio/dc/venv/lib/python3.12/site-packages/django/core/handlers/base.py", line 197, in _get_response
    response = wrapped_callback(request, *callback_args, **callback_kwargs)
               ^^^^^^^^^^^^^^^^^^^^^^^^^^^^^^^^^^^^^^^^^^^^^^^^^^^^^^^^^^^^
  File "/home/kaleyvo/Escritorio/dc/venv/lib/python3.12/site-packages/django/utils/decorators.py", line 48, in _wrapper
    return bound_method(*args, **kwargs)
           ^^^^^^^^^^^^^^^^^^^^^^^^^^^^^
  File "/home/kaleyvo/Escritorio/dc/venv/lib/python3.12/site-packages/django/views/decorators/cache.py", line 80, in _view_wrapper
    response = view_func(request, *args, **kwargs)
               ^^^^^^^^^^^^^^^^^^^^^^^^^^^^^^^^^^^
  File "/home/kaleyvo/Escritorio/dc/venv/lib/python3.12/site-packages/django/contrib/admin/sites.py", line 449, in login
    return LoginView.as_view(**defaults)(request)
           ^^^^^^^^^^^^^^^^^^^^^^^^^^^^^^^^^^^^^^
  File "/home/kaleyvo/Escritorio/dc/venv/lib/python3.12/site-packages/django/views/generic/base.py", line 104, in view
    return self.dispatch(request, *args, **kwargs)
           ^^^^^^^^^^^^^^^^^^^^^^^^^^^^^^^^^^^^^^^
  File "/home/kaleyvo/Escritorio/dc/venv/lib/python3.12/site-packages/django/utils/decorators.py", line 48, in _wrapper
    return bound_method(*args, **kwargs)
           ^^^^^^^^^^^^^^^^^^^^^^^^^^^^^
  File "/home/kaleyvo/Escritorio/dc/venv/lib/python3.12/site-packages/django/utils/decorators.py", line 48, in _wrapper
    return bound_method(*args, **kwargs)
           ^^^^^^^^^^^^^^^^^^^^^^^^^^^^^
  File "/home/kaleyvo/Escritorio/dc/venv/lib/python3.12/site-packages/django/views/decorators/debug.py", line 143, in sensitive_post_parameters_wrapper
    return view(request, *args, **kwargs)
           ^^^^^^^^^^^^^^^^^^^^^^^^^^^^^^
  File "/home/kaleyvo/Escritorio/dc/venv/lib/python3.12/site-packages/django/utils/decorators.py", line 48, in _wrapper
    return bound_method(*args, **kwargs)
           ^^^^^^^^^^^^^^^^^^^^^^^^^^^^^
  File "/home/kaleyvo/Escritorio/dc/venv/lib/python3.12/site-packages/django/utils/decorators.py", line 192, in _view_wrapper
    result = _process_exception(request, e)
             ^^^^^^^^^^^^^^^^^^^^^^^^^^^^^^
  File "/home/kaleyvo/Escritorio/dc/venv/lib/python3.12/site-packages/django/utils/decorators.py", line 190, in _view_wrapper
    response = view_func(request, *args, **kwargs)
               ^^^^^^^^^^^^^^^^^^^^^^^^^^^^^^^^^^^
  File "/home/kaleyvo/Escritorio/dc/venv/lib/python3.12/site-packages/django/utils/decorators.py", line 48, in _wrapper
    return bound_method(*args, **kwargs)
           ^^^^^^^^^^^^^^^^^^^^^^^^^^^^^
  File "/home/kaleyvo/Escritorio/dc/venv/lib/python3.12/site-packages/django/views/decorators/cache.py", line 80, in _view_wrapper
    response = view_func(request, *args, **kwargs)
               ^^^^^^^^^^^^^^^^^^^^^^^^^^^^^^^^^^^
  File "/home/kaleyvo/Escritorio/dc/venv/lib/python3.12/site-packages/django/contrib/auth/views.py", line 89, in dispatch
    return super().dispatch(request, *args, **kwargs)
           ^^^^^^^^^^^^^^^^^^^^^^^^^^^^^^^^^^^^^^^^^^
  File "/home/kaleyvo/Escritorio/dc/venv/lib/python3.12/site-packages/django/views/generic/base.py", line 143, in dispatch
    return handler(request, *args, **kwargs)
           ^^^^^^^^^^^^^^^^^^^^^^^^^^^^^^^^^
  File "/home/kaleyvo/Escritorio/dc/venv/lib/python3.12/site-packages/django/views/generic/edit.py", line 151, in post
    return self.form_valid(form)
           ^^^^^^^^^^^^^^^^^^^^^
  File "/home/kaleyvo/Escritorio/dc/venv/lib/python3.12/site-packages/django/contrib/auth/views.py", line 108, in form_valid
    auth_login(self.request, form.get_user())
  File "/home/kaleyvo/Escritorio/dc/venv/lib/python3.12/site-packages/django/contrib/auth/__init__.py", line 197, in login
    user_logged_in.send(sender=user.__class__, request=request, user=user)
  File "/home/kaleyvo/Escritorio/dc/venv/lib/python3.12/site-packages/django/dispatch/dispatcher.py", line 189, in send
    response = receiver(signal=self, sender=sender, **named)
               ^^^^^^^^^^^^^^^^^^^^^^^^^^^^^^^^^^^^^^^^^^^^^
  File "/home/kaleyvo/Escritorio/dc/venv/lib/python3.12/site-packages/django/contrib/auth/models.py", line 24, in update_last_login
    user.save(update_fields=["last_login"])
  File "/home/kaleyvo/Escritorio/dc/venv/lib/python3.12/site-packages/django/contrib/auth/base_user.py", line 65, in save
    super().save(*args, **kwargs)
  File "/home/kaleyvo/Escritorio/dc/venv/lib/python3.12/site-packages/django/db/models/base.py", line 902, in save
    self.save_base(
  File "/home/kaleyvo/Escritorio/dc/venv/lib/python3.12/site-packages/django/db/models/base.py", line 1023, in save_base
    post_save.send(
  File "/home/kaleyvo/Escritorio/dc/venv/lib/python3.12/site-packages/django/dispatch/dispatcher.py", line 189, in send
    response = receiver(signal=self, sender=sender, **named)
               ^^^^^^^^^^^^^^^^^^^^^^^^^^^^^^^^^^^^^^^^^^^^^
  File "/home/kaleyvo/Escritorio/dc/users/signals.py", line 12, in save_profile
    instance.profile.save()
    ^^^^^^^^^^^^^^^^
  File "/home/kaleyvo/Escritorio/dc/venv/lib/python3.12/site-packages/django/db/models/fields/related_descriptors.py", line 531, in __get__
    raise self.RelatedObjectDoesNotExist(
users.models.user.CustomUser.profile.RelatedObjectDoesNotExist: CustomUser has no profile.
ERROR 2025-05-14 14:09:43,847 basehttp "POST /admin/login/?next=/admin/ HTTP/1.1" 500 145
ERROR 2025-05-14 21:02:03,740 log Internal Server Error: /admin/login/
Traceback (most recent call last):
  File "/home/kaleyvo/Escritorio/dc/venv/lib/python3.12/site-packages/django/core/handlers/exception.py", line 55, in inner
    response = get_response(request)
               ^^^^^^^^^^^^^^^^^^^^^
  File "/home/kaleyvo/Escritorio/dc/venv/lib/python3.12/site-packages/django/core/handlers/base.py", line 197, in _get_response
    response = wrapped_callback(request, *callback_args, **callback_kwargs)
               ^^^^^^^^^^^^^^^^^^^^^^^^^^^^^^^^^^^^^^^^^^^^^^^^^^^^^^^^^^^^
  File "/home/kaleyvo/Escritorio/dc/venv/lib/python3.12/site-packages/django/utils/decorators.py", line 48, in _wrapper
    return bound_method(*args, **kwargs)
           ^^^^^^^^^^^^^^^^^^^^^^^^^^^^^
  File "/home/kaleyvo/Escritorio/dc/venv/lib/python3.12/site-packages/django/views/decorators/cache.py", line 80, in _view_wrapper
    response = view_func(request, *args, **kwargs)
               ^^^^^^^^^^^^^^^^^^^^^^^^^^^^^^^^^^^
  File "/home/kaleyvo/Escritorio/dc/venv/lib/python3.12/site-packages/django/contrib/admin/sites.py", line 449, in login
    return LoginView.as_view(**defaults)(request)
           ^^^^^^^^^^^^^^^^^^^^^^^^^^^^^^^^^^^^^^
  File "/home/kaleyvo/Escritorio/dc/venv/lib/python3.12/site-packages/django/views/generic/base.py", line 104, in view
    return self.dispatch(request, *args, **kwargs)
           ^^^^^^^^^^^^^^^^^^^^^^^^^^^^^^^^^^^^^^^
  File "/home/kaleyvo/Escritorio/dc/venv/lib/python3.12/site-packages/django/utils/decorators.py", line 48, in _wrapper
    return bound_method(*args, **kwargs)
           ^^^^^^^^^^^^^^^^^^^^^^^^^^^^^
  File "/home/kaleyvo/Escritorio/dc/venv/lib/python3.12/site-packages/django/utils/decorators.py", line 48, in _wrapper
    return bound_method(*args, **kwargs)
           ^^^^^^^^^^^^^^^^^^^^^^^^^^^^^
  File "/home/kaleyvo/Escritorio/dc/venv/lib/python3.12/site-packages/django/views/decorators/debug.py", line 143, in sensitive_post_parameters_wrapper
    return view(request, *args, **kwargs)
           ^^^^^^^^^^^^^^^^^^^^^^^^^^^^^^
  File "/home/kaleyvo/Escritorio/dc/venv/lib/python3.12/site-packages/django/utils/decorators.py", line 48, in _wrapper
    return bound_method(*args, **kwargs)
           ^^^^^^^^^^^^^^^^^^^^^^^^^^^^^
  File "/home/kaleyvo/Escritorio/dc/venv/lib/python3.12/site-packages/django/utils/decorators.py", line 192, in _view_wrapper
    result = _process_exception(request, e)
             ^^^^^^^^^^^^^^^^^^^^^^^^^^^^^^
  File "/home/kaleyvo/Escritorio/dc/venv/lib/python3.12/site-packages/django/utils/decorators.py", line 190, in _view_wrapper
    response = view_func(request, *args, **kwargs)
               ^^^^^^^^^^^^^^^^^^^^^^^^^^^^^^^^^^^
  File "/home/kaleyvo/Escritorio/dc/venv/lib/python3.12/site-packages/django/utils/decorators.py", line 48, in _wrapper
    return bound_method(*args, **kwargs)
           ^^^^^^^^^^^^^^^^^^^^^^^^^^^^^
  File "/home/kaleyvo/Escritorio/dc/venv/lib/python3.12/site-packages/django/views/decorators/cache.py", line 80, in _view_wrapper
    response = view_func(request, *args, **kwargs)
               ^^^^^^^^^^^^^^^^^^^^^^^^^^^^^^^^^^^
  File "/home/kaleyvo/Escritorio/dc/venv/lib/python3.12/site-packages/django/contrib/auth/views.py", line 89, in dispatch
    return super().dispatch(request, *args, **kwargs)
           ^^^^^^^^^^^^^^^^^^^^^^^^^^^^^^^^^^^^^^^^^^
  File "/home/kaleyvo/Escritorio/dc/venv/lib/python3.12/site-packages/django/views/generic/base.py", line 143, in dispatch
    return handler(request, *args, **kwargs)
           ^^^^^^^^^^^^^^^^^^^^^^^^^^^^^^^^^
  File "/home/kaleyvo/Escritorio/dc/venv/lib/python3.12/site-packages/django/views/generic/edit.py", line 151, in post
    return self.form_valid(form)
           ^^^^^^^^^^^^^^^^^^^^^
  File "/home/kaleyvo/Escritorio/dc/venv/lib/python3.12/site-packages/django/contrib/auth/views.py", line 108, in form_valid
    auth_login(self.request, form.get_user())
  File "/home/kaleyvo/Escritorio/dc/venv/lib/python3.12/site-packages/django/contrib/auth/__init__.py", line 197, in login
    user_logged_in.send(sender=user.__class__, request=request, user=user)
  File "/home/kaleyvo/Escritorio/dc/venv/lib/python3.12/site-packages/django/dispatch/dispatcher.py", line 189, in send
    response = receiver(signal=self, sender=sender, **named)
               ^^^^^^^^^^^^^^^^^^^^^^^^^^^^^^^^^^^^^^^^^^^^^
  File "/home/kaleyvo/Escritorio/dc/venv/lib/python3.12/site-packages/django/contrib/auth/models.py", line 24, in update_last_login
    user.save(update_fields=["last_login"])
  File "/home/kaleyvo/Escritorio/dc/venv/lib/python3.12/site-packages/django/contrib/auth/base_user.py", line 65, in save
    super().save(*args, **kwargs)
  File "/home/kaleyvo/Escritorio/dc/venv/lib/python3.12/site-packages/django/db/models/base.py", line 902, in save
    self.save_base(
  File "/home/kaleyvo/Escritorio/dc/venv/lib/python3.12/site-packages/django/db/models/base.py", line 1023, in save_base
    post_save.send(
  File "/home/kaleyvo/Escritorio/dc/venv/lib/python3.12/site-packages/django/dispatch/dispatcher.py", line 189, in send
    response = receiver(signal=self, sender=sender, **named)
               ^^^^^^^^^^^^^^^^^^^^^^^^^^^^^^^^^^^^^^^^^^^^^
  File "/home/kaleyvo/Escritorio/dc/users/signals.py", line 12, in save_profile
    instance.profile.save()
    ^^^^^^^^^^^^^^^^
  File "/home/kaleyvo/Escritorio/dc/venv/lib/python3.12/site-packages/django/db/models/fields/related_descriptors.py", line 531, in __get__
    raise self.RelatedObjectDoesNotExist(
users.models.user.CustomUser.profile.RelatedObjectDoesNotExist: CustomUser has no profile.
ERROR 2025-05-14 21:02:03,771 basehttp "POST /admin/login/?next=/admin/ HTTP/1.1" 500 145
